<robot name = "xarm7">
    <material name="white">
    <color rgba="1.0 1.0 1.0 1.0"/>
    </material>

    <link name = "base_link">
        <visual>
            <origin xyz = "0 0 0" rpy = "0 0 0"/> 
            <geometry>
                <mesh filename = "package://ufactory_xarm7_description/meshes/link_base.stl" 
                scale="1.0 1.0 1.0"/>
            </geometry>
            <material name="white"/>
        </visual>
    </link>


    <link name="link1">
        <visual>
            <origin xyz = "0 0 0" rpy = "0 0 0"/>   
            <geometry>
              <mesh filename="package://ufactory_xarm7_description/meshes/link1.stl" scale="1.0 1.0 1.0"/>
            </geometry>
            <material name="white"/>
        </visual>
    </link>

    <link name="link2">
        <visual>
            <origin xyz = "0 0 0" rpy = "0 0 0"/>   
            <geometry>
              <mesh filename="package://ufactory_xarm7_description/meshes/link2.stl" scale="1.0 1.0 1.0"/>
            </geometry>
            <material name="white"/>
        </visual>
    </link>

    <link name="link3">
        <visual>
            <origin xyz = "0 0 0" rpy = "0 0 0"/>   
            <geometry>
              <mesh filename="package://ufactory_xarm7_description/meshes/link3.stl" scale="1.0 1.0 1.0"/>
            </geometry>
            <material name="white"/>
        </visual>
    </link>

    <link name="link4">
        <visual>
            <origin xyz = "0 0 0" rpy = "0 0 0"/>   
            <geometry>
              <mesh filename="package://ufactory_xarm7_description/meshes/link4.stl" scale="1.0 1.0 1.0"/>
            </geometry>
            <material name="white"/>
        </visual>
    </link>

    <link name="link5">
        <visual>
            <origin xyz = "0 0 0" rpy = "0 0 0"/>   
            <geometry>
              <mesh filename="package://ufactory_xarm7_description/meshes/link5.stl" scale="1.0 1.0 1.0"/>
            </geometry>
            <material name="white"/>
        </visual>
    </link>

    <link name="link6">
        <visual>
            <origin xyz = "0 0 0" rpy = "0 0 0"/>   
            <geometry>
              <mesh filename="package://ufactory_xarm7_description/meshes/link6.stl" scale="1.0 1.0 1.0"/>
            </geometry>
            <material name="white"/>
        </visual>
    </link>

    <link name="link7">
        <visual>
            <origin xyz = "0 0 0" rpy = "0 0 0"/>   
            <geometry>
              <mesh filename="package://ufactory_xarm7_description/meshes/link7.stl" scale="1.0 1.0 1.0"/>
            </geometry>
            <material name="white"/>
        </visual>
    </link>

    <link name="gripper">
        <visual>
            <origin xyz = "0 0 0" rpy = "0 0 0"/>   
            <geometry>
              <mesh filename="package://ufactory_xarm7_description/meshes/gripper_lite.stl" scale="1.0 1.0 1.0"/>
            </geometry>
            <material name="white"/>
        </visual>
    </link>

   
    <joint name="base_link_to_link1" type="revolute">
        <origin xyz="0 0 0.25" rpy="0.0 0.0 0.0"/>
        <parent link="base_link"/>
        <child link="link1"/>
        <axis xyz="0 1 0"/>
        <limit lower="-6.283" upper="6.283" effort="3.0" velocity="3.14"/>
       
    </joint>

    <joint name="link1_to_link2" type="revolute">
        <origin xyz="0 0 0" rpy="1.57 3.1416 3.1416"/>
        <parent link="link1"/>
        <child link="link2"/>
        <axis xyz="0 1 0"/>
        <limit lower="-2.059" upper="2.094" effort="3.0" velocity="3.14"/>
    </joint>

    <joint name="link2_to_link3" type="revolute">
        <origin xyz="0.05 -0.25 0" rpy="0.0 0.0 3.1416"/>
        <parent link="link2"/>
        <child link="link3"/>
        <axis xyz="0 1 0"/>
        <limit lower="-6.283" upper="6.283" effort="3.0" velocity="3.14"/>
    </joint>

    <joint name="link3_to_link4" type="revolute">
        <origin xyz="0 0 -0.03" rpy="0.0 3.1416 0.0"/>
        <parent link="link3"/>
        <child link="link4"/>
        <axis xyz="0 1 0"/>
        <limit lower="-0.192" upper="3.927" effort="3.0" velocity="3.14"/>
    </joint>

    <joint name="link4_to_link5" type="revolute">
        <origin xyz="0.077 -0.33 0" rpy="1.57 0.0 0.0"/>
        <parent link="link4"/>
        <child link="link5"/>
        <axis xyz="0 1 0"/>
        <limit lower="-6.283" upper="6.283" effort="3.0" velocity="3.14"/>
    </joint>

    <joint name="link5_to_link6" type="revolute">
        <origin xyz="0 0 0" rpy="1.57 0.0 0.0"/>
        <parent link="link5"/>
        <child link="link6"/>
        <axis xyz="0 1 0"/>
        <limit lower="-1.692" upper="3.142" effort="3.0" velocity="3.14"/>
    </joint>

    <joint name="link6_to_link7" type="revolute">
        <origin xyz="0 0 0" rpy="0.0 0.0 0.0"/>
        <parent link="link6"/>
        <child link="link7"/>
        <axis xyz="0 1 0"/>
        <limit lower="-6.283" upper="6.283" effort="3.0" velocity="3.14"/>
    </joint>

    <joint name="link7_to_gripper" type="fixed">
        <origin xyz="0.077 0.0605 0.0" rpy="-1.571 1.571 0.0"/>
        <parent link="link7"/>
        <child link="gripper"/>
    </joint>




</robot>