<?xml version="1.0" ?>
<!-- =================================================================================== -->
<!-- |    This document was autogenerated by xacro from /mnt/c/Users/abdul/Documents/Aurora_Robotics/abdullahi_Task4/src/ufactory_xarm7_description/urdf/xarm7.urdf.xacro | -->
<!-- |    EDITING THIS FILE BY HAND IS NOT RECOMMENDED                                 | -->
<!-- =================================================================================== -->
<robot name="ufactory-xarm7-robot">
  <joint name="base_link_to_link1" type="revolute">
    <origin rpy="0.0 0.0 0.0" xyz="0.0 0.0 0.15"/>
    <parent link="base_link"/>
    <child link="link1"/>
    <axis xyz="0 1 0"/>
    <limit effort="3.0" lower="-6.283" upper="6.283" velocity="3.14"/>
  </joint>
  <joint name="link1_to_link2" type="revolute">
    <origin rpy="0.0 0.0 0.0" xyz="0.0 0.077 0.11"/>
    <parent link="link1"/>
    <child link="link2"/>
    <axis xyz="0 1 0"/>
    <limit effort="3.0" lower="-2.059" upper="2.094" velocity="3.14"/>
  </joint>
  <joint name="link2_to_link3" type="revolute">
    <origin rpy="0.0 0.0 0.0" xyz="0.0 -0.075 0.18"/>
    <parent link="link2"/>
    <child link="link3"/>
    <axis xyz="0 1 0"/>
    <limit effort="3.0" lower="-6.283" upper="6.283" velocity="3.14"/>
  </joint>
  <joint name="link3_to_link4" type="revolute">
    <origin rpy="0.0 0.0 0.0" xyz="0.055 -0.055 0.099"/>
    <parent link="link3"/>
    <child link="link4"/>
    <axis xyz="0 1 0"/>
    <limit effort="3.0" lower="-0.192" upper="3.927" velocity="3.14"/>
  </joint>
  <joint name="link4_to_link5" type="revolute">
    <origin rpy="0.0 0.0 0.0" xyz="0.078 0.058 -0.16"/>
    <parent link="link4"/>
    <child link="link5"/>
    <axis xyz="0 1 0"/>
    <limit effort="3.0" lower="-6.283" upper="6.283" velocity="3.14"/>
  </joint>
  <joint name="link5_to_link6" type="revolute">
    <origin rpy="0.0 0.0 0.0" xyz="0.0 0.0 -0.17"/>
    <parent link="link5"/>
    <child link="link6"/>
    <axis xyz="0 1 0"/>
    <limit effort="3.0" lower="-1.692" upper="3.142" velocity="3.14"/>
  </joint>
  <joint name="link6_to_link7" type="revolute">
    <origin rpy="0.0 0.0 0.0" xyz="0.072 0.0 -0.072"/>
    <parent link="link6"/>
    <child link="link7"/>
    <axis xyz="0 1 0"/>
    <limit effort="3.0" lower="-6.283" upper="6.283" velocity="3.14"/>
  </joint>
  <joint name="link7_to_gripper" type="fixed">
    <origin rpy="0.0 0.0 0.0" xyz="0.0 0.0 -0.02"/>
    <parent link="link7"/>
    <child link="gripper"/>
  </joint>

  
  <link name="base_link">
    <visual>
      <origin rpy="0.0 0.0 0.0" xyz="0.0 0.0 0.0"/>
      <geometry>
        <mesh filename="package://ufactory_xarm7_description/meshes/link_base.stl"/>
      </geometry>
      <material name="white"/>
    </visual>
    <collision>
      <origin rpy="0.0 0.0 0.0" xyz="0.0 0.0 0.0"/>
      <geometry>
        <mesh filename="package://ufactory_xarm7_description/meshes/link_base.stl"/>
      </geometry>
    </collision>
  </link>
  <link name="link1">
    <visual>
      <origin rpy="0.0 0.0 0.0" xyz="0.0 0.0 0.11"/>
      <geometry>
        <mesh filename="package://ufactory_xarm7_description/meshes/link1.stl"/>
      </geometry>
      <material name="white"/>
    </visual>
    <collision>
      <origin rpy="0.0 0.0 0.0" xyz="0.0 0.0 0.11"/>
      <geometry>
        <mesh filename="package://ufactory_xarm7_description/meshes/link1.stl"/>
      </geometry>
    </collision>
  </link>
  <link name="link2">
    <visual>
      <origin rpy="-1.57 0.0 0.0" xyz="0.0 -0.077 0.0"/>
      <geometry>
        <mesh filename="package://ufactory_xarm7_description/meshes/link2.stl"/>
      </geometry>
      <material name="white"/>
    </visual>
    <collision>
      <origin rpy="-1.57 0.0 0.0" xyz="0.0 -0.077 0.0"/>
      <geometry>
        <mesh filename="package://ufactory_xarm7_description/meshes/link2.stl"/>
      </geometry>
    </collision>
  </link>
  <link name="link3">
    <visual>
      <origin rpy="0.0 0.0 0.0" xyz="0.0 0.0 0.10"/>
      <geometry>
        <mesh filename="package://ufactory_xarm7_description/meshes/link3.stl"/>
      </geometry>
      <material name="white"/>
    </visual>
    <collision>
      <origin rpy="0.0 0.0 0.0" xyz="0.0 0.0 0.10"/>
      <geometry>
        <mesh filename="package://ufactory_xarm7_description/meshes/link3.stl"/>
      </geometry>
    </collision>
  </link>
  <link name="link4">
    <visual>
      <origin rpy="1.577 0.0 0.0" xyz="0.0 0.055 0.0"/>
      <geometry>
        <mesh filename="package://ufactory_xarm7_description/meshes/link4.stl"/>
      </geometry>
      <material name="white"/>
    </visual>
    <collision>
      <origin rpy="1.577 0.0 0.0" xyz="0.0 0.055 0.0"/>
      <geometry>
        <mesh filename="package://ufactory_xarm7_description/meshes/link4.stl"/>
      </geometry>
    </collision>
  </link>
  <link name="link5">
    <visual>
      <origin rpy="3.14 0.0 0.0" xyz="0.0 0.0 -0.17"/>
      <geometry>
        <mesh filename="package://ufactory_xarm7_description/meshes/link5.stl"/>
      </geometry>
      <material name="white"/>
    </visual>
    <collision>
      <origin rpy="3.14 0.0 0.0" xyz="0.0 0.0 -0.17"/>
      <geometry>
        <mesh filename="package://ufactory_xarm7_description/meshes/link5.stl"/>
      </geometry>
    </collision>
  </link>
  <link name="link6">
    <visual>
      <origin rpy="-1.571 0.0 0.0" xyz="0.0 0.0 0.0"/>
      <geometry>
        <mesh filename="package://ufactory_xarm7_description/meshes/link6.stl"/>
      </geometry>
      <material name="white"/>
    </visual>
    <collision>
      <origin rpy="-1.571 0.0 0.0" xyz="0.0 0.0 0.0"/>
      <geometry>
        <mesh filename="package://ufactory_xarm7_description/meshes/link6.stl"/>
      </geometry>
    </collision>
  </link>
  <link name="link7">
    <visual>
      <origin rpy="3.142 0.0 0.0" xyz="0.0 0.0 -0.028"/>
      <geometry>
        <mesh filename="package://ufactory_xarm7_description/meshes/link7.stl"/>
      </geometry>
      <material name="white"/>
    </visual>
    <collision>
      <origin rpy="3.142 0.0 0.0" xyz="0.0 0.0 -0.028"/>
      <geometry>
        <mesh filename="package://ufactory_xarm7_description/meshes/link7.stl"/>
      </geometry>
    </collision>
  </link>
  <link name="gripper">
    <visual>
      <origin rpy="3.142 0.0 1.57" xyz="0.0 0.0 0.0"/>
      <geometry>
        <mesh filename="package://ufactory_xarm7_description/meshes/gripper_lite.stl"/>
      </geometry>
      <material name="white"/>
    </visual>
    <collision>
      <origin rpy="3.142 0.0 1.57" xyz="0.0 0.0 0.0"/>
      <geometry>
        <mesh filename="package://ufactory_xarm7_description/meshes/gripper_lite.stl"/>
      </geometry>
    </collision>
  </link>
  <material name="white">
    <color rgba="1 1 1 1"/>
  </material>
</robot>
